<!doctype html>
<html lang="ru">
  <head>
    <meta charset="utf-8">
    <link rel="shortcut icon" href="../../images/image.jpg" type="image/x-icon">
    <meta name="viewport" content="width=device-width, initial-scale=1.0">
    <title>JS</title>
    <link rel="stylesheet" href="../../styles/style.css">
    <link rel="stylesheet" href="../../styles/prism.css">
    <script src="../../scripts/prism.js" defer></script>
    <script src="../../scripts/script.js" defer></script>
  </head>

  <body>
    <!--шапка с кнопками переходами-->
    <header class="main-header-top">
      <div class="header-logo">
        <img src="../../images/image2.png">
      </div>
      
      <ul>
        <li><a href="../../index.html">Home</a></li>
        <li><a href="../../pages/html.html">HTML</a></li>
        <li><a href="../../pages/css.html">CSS</a></li>
        <li><a href="../../pages/js.html">JS</a></li>
      </ul>
    </header>

    <!--основной блок с информацией-->
    <main>
      <article>
        <h1>Конструкции try, catch, finally</h1><hr>
        <p>Обработка ошибок является одной из ключевых задач в программировании. Конструкции <code>try</code>, <code>catch</code>, и <code>finally</code> в JavaScript предоставляют мощный механизм для обработки исключений, предотвращая аварийное завершение программы.</p>
        <h3>1. Что такое try, catch и finally?</h3>
        <p>Эти конструкции используются для обработки ошибок в блоке кода. Основная задача — захватить исключение (ошибку), которое возникает во время выполнения программы, и предоставить способ справиться с этой ошибкой, не прерывая выполнение всего приложения.</p>
        <ul>
          <li><code>try</code>: Блок кода, где может произойти ошибка.</li>
          <li><code>catch</code>: Блок кода, который обрабатывает ошибку, если она возникла в блоке try.</li>
          <li><code>finally</code> (опционально): Блок кода, который выполняется в любом случае — была ошибка или нет.</li>
        </ul>
        <h3>2. Синтаксис</h3>
<pre>
  <code class="lang-js">
    try {
      // Код, который потенциально может вызвать ошибку
    } catch (error) {
      // Код для обработки ошибки
    } finally {
      // Код, который выполнится в любом случае (опционально)
    }
  </code>
</pre>
        <p>Пример:</p>
<pre>
  <code class="lang-js">
    try {
      let result = 10 / 0; // Ошибки не будет, но результат Infinity
        console.log(result);
        console.log(undeclaredVariable); // Эта строка вызовет ошибку
    } catch (error) {
        console.log("Произошла ошибка:", error.message);
    } finally {
        console.log("Этот код выполнится в любом случае");
    }
  </code>
</pre>
        <p>Вывод:</p>
<pre>
  <code>
    Infinity
    Произошла ошибка: undeclaredVariable is not defined
    Этот код выполнится в любом случае
  </code>
</pre>
        <h3>3. Детали работы try, catch</h3>
        <h4>3.1. Блок try</h4>
        <p>Внутри блока <code>try</code> размещается код, который может вызвать ошибку. Ошибки могут быть как синтаксическими (ошибки разработчика), так и логическими (например, деление на ноль или попытка доступа к несуществующему свойству).</p>
        <ul>
          <li>Если ошибка не возникает, код <code>catch</code> игнорируется.</li>
          <li>Если возникает ошибка, выполнение <code>try</code> прекращается, и управление передается в <code>catch</code>.</li>
        </ul>
        <h4>3.2. Блок catch</h4>
        <p>Блок catch перехватывает ошибки, возникшие в try. Обработчик принимает объект ошибки как аргумент, который содержит информацию об ошибке.</p>
        <p>Пример:</p>
<pre>
  <code class="lang-js">
    try {
      JSON.parse("{invalidJson}"); // Некорректный JSON
    } catch (error) {
        console.log("Ошибка:", error.name); // Тип ошибки
        console.log("Сообщение:", error.message); // Описание ошибки
    }
  </code>
</pre>
        <p>Вывод:</p>
<pre>
  <code>
    Ошибка: SyntaxError
    Сообщение: Unexpected token i in JSON at position 1
  </code>
</pre>
        <h4>3.3. Блок finally</h4>
        <p>Блок <code>finally</code> выполняется всегда:</p>
        <ul>
          <li>Если ошибка произошла.</li>
          <li>Если ошибки не было.</li>
          <li>Даже если в <code>try</code> или <code>catch</code> есть <code>return</code>.</li>
        </ul>
        <p>Пример:</p>
<pre>
  <code class="lang-js">
    function testFinally() {
      try {
        console.log("Выполняется блок try");
        return "Возврат из try";
      } catch (error) {
          console.log("Ошибка:", error.message);
      } finally {
          console.log("Блок finally выполнен");
      }
    }
  
    console.log(testFinally());
  </code>
</pre>
        <p>Вывод:</p>
<pre>
  <code>
    Выполняется блок try
    Блок finally выполнен
    Возврат из try
  </code>
</pre>
        <h3>4. Искусственное создание ошибок</h3>
        <p>JavaScript позволяет искусственно вызывать ошибки с помощью оператора <code>throw</code>. Это полезно для проверки обработки ошибок или для генерации собственных сообщений об ошибках.</p>
        <h4>Синтаксис throw</h4>
<pre>
  <code class="lang-js">
    throw выражение;
  </code>
</pre>
        <p>Пример:</p>
<pre>
  <code class="lang-js">
    try {
      let age = -5;
      if (age < 0) {
        throw new Error("Возраст не может быть отрицательным!");
      }
    } catch (error) {
        console.log("Произошла ошибка:", error.message);
    }
  </code>
</pre>
        <p>Вывод:</p>
<pre>
  <code>
    Произошла ошибка: Возраст не может быть отрицательным!
  </code>
</pre>
        <h3>5. Типы ошибок в JavaScript</h3>
        <h4>5.1. Встроенные ошибки</h4>
        <p>JavaScript имеет встроенные типы ошибок, которые можно перехватывать:</p>
        <ul>
          <li><code>Error</code>: Базовый класс всех ошибок.</li>
          <li><code>SyntaxError</code>: Ошибка синтаксиса.</li>
          <li><code>TypeError</code>: Ошибка типа (например, вызов не-функции как функции).</li>
          <li><code>ReferenceError</code>: Попытка обращения к необъявленной переменной.</li>
          <li><code>RangeError</code>: Ошибка диапазона (например, бесконечный цикл в рекурсии).</li>
          <li><code>URIError</code>: Ошибка при неправильном использовании URI-функций (например, decodeURIComponent).</li>
        </ul>
        <p>Пример:</p>
<pre>
  <code class="lang-js">
    try {
      null.test(); // Попытка доступа к свойству у null
    } catch (error) {
        console.log("Тип ошибки:", error.name);
        console.log("Сообщение:", error.message);
    }
  </code>
</pre>
        <h3>6. Особенности обработки ошибок</h3>
        <h4>6.1. Локальные и глобальные ошибки</h4>
        <p>Не все ошибки можно обработать с помощью <code>try...catch</code>. Например:</p>
        <ul>
          <li>Ошибки синтаксиса невозможно перехватить, потому что они возникают до выполнения кода.</li>
          <li>Глобальные ошибки, которые не перехвачены <code>try...catch</code>, можно обрабатывать с помощью обработчика <code>window.onerror</code> в браузере.</li>
        </ul>
        <p>Пример:</p>
<pre>
  <code class="lang-js">
    window.onerror = function (message, source, lineno, colno, error) {
      console.log("Глобальная ошибка:", message);
    };
    console.log(undeclaredVariable); // Глобальная ошибка
  </code>
</pre>
        <h4>6.2. Асинхронные операции</h4>
        <p>Блоки <code>try...catch</code> не обрабатывают ошибки в асинхронном коде, если не используется <code>await</code> (в случае промисов). Для этого нужно использовать методы промисов или <code>async/await</code>.</p>
        <p>Пример с промисами:</p>
<pre>
  <code class="lang-js">
    Promise.reject(new Error("Асинхронная ошибка"))
      .catch(error => console.log("Обработано:", error.message));
  </code>
</pre>
        <p>Пример с <code>async/await:</code></p>
<pre>
  <code class="lang-js">
    (async function() {
      try {
        await Promise.reject(new Error("Ошибка в async/await"));
      } catch (error) {
          console.log("Ошибка обработана:", error.message);
      }
    })();
  </code>
</pre>
        <h3>7. Продвинутые приемы</h3>
        <h4>7.1. Вложенные блоки try...catch</h4>
        <p>Можно использовать несколько уровней <code>try...catch</code> для более детальной обработки.</p>
        <p>Пример:</p>
<pre>
  <code class="lang-js">
    try {
      try {
        throw new Error("Внутренняя ошибка");
      } catch (innerError) {
          console.log("Внутренний catch:", innerError.message);
          throw new Error("Внешняя ошибка");
      }
    } catch (outerError) {
        console.log("Внешний catch:", outerError.message);
    }
  </code>
</pre>
        <p>Вывод:</p>
<pre>
  <code>
    Внутренний catch: Внутренняя ошибка
    Внешний catch: Внешняя ошибка
  </code>
</pre>
        <h4>7.2. Использование пользовательских ошибок</h4>
        <p>Для создания собственных ошибок можно наследоваться от класса Error.</p>
        <p>Пример:</p>
<pre>
  <code class="lang-js">
    class CustomError extends Error {
      constructor(message) {
        super(message);
        this.name = "CustomError";
      }
    }
  
    try {
      throw new CustomError("Это пользовательская ошибка");
    } catch (error) {
        console.log(error.name + ": " + error.message);
    }
  </code>
</pre>
        <p>Вывод:</p>
<pre>
  <code>
    CustomError: Это пользовательская ошибка
  </code>
</pre>
        <h3>8. Практические советы</h3>
        <ul>
          <li>Используйте <code>try...catch</code> для обработки предсказуемых ошибок.</li>
          <li>Не злоупотребляйте <code>try...catch</code> для логики программы. Лучше проверять условия с помощью <code>if</code>.</li>
          <li>Логируйте ошибки, чтобы упростить отладку.</li>
        </ul>

       



      </article>
    </main>

    <!--блок в нижней части страницы-->
    <footer> 
      <p>©Copyright 2024 by nobody. All rights reversed.</p>
    </footer>

  </body>
</html>